<?xml version='1.0'?>
<robot name="mower_v1">

  <!-- Base Link -->
  <link name="base_link">
    <visual>
      <origin xyz="0 0 0" rpy="0 0 0" />
      <geometry>
          <box size="0.8 0.4 0.5"/>
      </geometry>
      <material name="blue">
        <color rgba="0 0.5 1 1"/>
      </material>
    </visual>
    <collision>
      <origin xyz="0.0 0.0 0.0" rpy="0.0 0.0 0.0"/>
      <geometry>
        <box size="0.8 0.4 0.5"/>
      </geometry>
    </collision>
    <inertial>
      <mass value="3.5"/>
      <inertia ixx="0.0001" ixy="0.0" ixz="0.0" iyy="0.0001" iyz="0.0" izz="0.0001"/>
    </inertial>
  </link>

  <!--Front Right Wheel -->
  <link name="f_right_wheel">
    <visual>
      <origin xyz="0 0 0" rpy="1.570795 0 0" />
      <geometry>
          <cylinder length="0.1" radius="0.1" />
      </geometry>
      <material name="black">
        <color rgba="0.05 0.05 0.05 1"/>
      </material>
    </visual>
    <collision>
      <origin xyz="0.0 0.0 0.0" rpy="1.570795 0.0 0.0"/>
      <geometry>
          <cylinder radius="0.1" length="0.1"/>
      </geometry>
    </collision>
    <inertial>
      <mass value="0.5"/>
      <inertia ixx="0.01" ixy="0.0" ixz="0.0" iyy="0.005" iyz="0.0" izz="0.005"/>
    </inertial>
  </link>
  <joint name="joint_f_right_wheel" type="continuous">
    <parent link="base_link"/>
    <child link="f_right_wheel"/>
    <origin xyz="0.20 -0.25 -0.25" rpy="0 0 0" /> 
    <axis xyz="0 1 0" />
  </joint>

  <!--Front Left Wheel -->
  <link name="f_left_wheel">
    <visual>
      <origin xyz="0 0 0" rpy="1.570795 0 0" />
      <geometry>
          <cylinder length="0.1" radius="0.1" />
      </geometry>
      <material name="black">
        <color rgba="0.05 0.05 0.05 1"/>
      </material>
    </visual>
    <collision>
      <origin xyz="0.0 0.0 0.0" rpy="1.570795 0.0 0.0"/>
      <geometry>
          <cylinder radius="0.1" length="0.1"/>
      </geometry>
    </collision>
    <inertial>
      <mass value="0.5"/>
      <inertia ixx="0.01" ixy="0.0" ixz="0.0" iyy="0.005" iyz="0.0" izz="0.005"/>
    </inertial>
  </link>
  <joint name="joint_f_left_wheel" type="continuous">
    <parent link="base_link"/>
    <child link="f_left_wheel"/>
    <origin xyz="0.20 0.25 -0.25" rpy="0 0 0" /> 
    <axis xyz="0 1 0" />
  </joint>

  <!--Rear Right Wheel -->
  <link name="r_right_wheel">
    <visual>
      <origin xyz="0 0 0" rpy="1.570795 0 0" />
      <geometry>
          <cylinder length="0.1" radius="0.1" />
      </geometry>
      <material name="black">
        <color rgba="0.05 0.05 0.05 1"/>
      </material>
    </visual>
    <collision>
      <origin xyz="0.0 0.0 0.0" rpy="1.570795 0.0 0.0"/>
      <geometry>
          <cylinder radius="0.1" length="0.1"/>
      </geometry>
    </collision>
    <inertial>
      <mass value="0.5"/>
      <inertia ixx="0.01" ixy="0.0" ixz="0.0" iyy="0.005" iyz="0.0" izz="0.005"/>
    </inertial>
  </link>
  <joint name="joint_r_right_wheel" type="continuous">
    <parent link="base_link"/>
    <child link="r_right_wheel"/>
    <origin xyz="-0.30 -0.25 -0.25" rpy="0 0 0" /> 
    <axis xyz="0 1 0" />
  </joint>

  <!--Rear Left Wheel -->
  <link name="r_left_wheel">
    <visual>
      <origin xyz="0 0 0" rpy="1.570795 0 0" />
      <geometry>
          <cylinder length="0.1" radius="0.1" />
      </geometry>
      <material name="black">
        <color rgba="0.05 0.05 0.05 1"/>
      </material>
    </visual>
    <collision>
      <origin xyz="0.0 0.0 0.0" rpy="1.570795 0.0 0.0"/>
      <geometry>
          <cylinder radius="0.1" length="0.1"/>
      </geometry>
    </collision>
    <inertial>
      <mass value="0.5"/>
      <inertia ixx="0.01" ixy="0.0" ixz="0.0" iyy="0.005" iyz="0.0" izz="0.005"/>
    </inertial>
  </link>
  <joint name="joint_r_left_wheel" type="continuous">
    <parent link="base_link"/>
    <child link="r_left_wheel"/>
    <origin xyz="-0.30 0.25 -0.25" rpy="0 0 0" /> 
    <axis xyz="0 1 0" />
  </joint>

</robot>